[2021-10-03 06:35:52,418] {taskinstance.py:903} INFO - Dependencies all met for <TaskInstance: dag1.determine_integrity 2021-10-01T00:19:00+00:00 [queued]>
[2021-10-03 06:35:52,664] {taskinstance.py:903} INFO - Dependencies all met for <TaskInstance: dag1.determine_integrity 2021-10-01T00:19:00+00:00 [queued]>
[2021-10-03 06:35:52,672] {taskinstance.py:1095} INFO - 
--------------------------------------------------------------------------------
[2021-10-03 06:35:52,673] {taskinstance.py:1096} INFO - Starting attempt 1 of 1
[2021-10-03 06:35:52,678] {taskinstance.py:1097} INFO - 
--------------------------------------------------------------------------------
[2021-10-03 06:35:52,997] {taskinstance.py:1115} INFO - Executing <Task(BranchPythonOperator): determine_integrity> on 2021-10-01T00:19:00+00:00
[2021-10-03 06:35:53,221] {standard_task_runner.py:76} INFO - Running: ['***', 'tasks', 'run', 'dag1', 'determine_integrity', '2021-10-01T00:19:00+00:00', '--job-id', '48', '--pool', 'default_pool', '--raw', '--subdir', 'DAGS_FOLDER/upload_file_to_staging.py', '--cfg-path', '/tmp/tmp4lpnzac6', '--error-file', '/tmp/tmp513u7x4z']
[2021-10-03 06:35:53,241] {standard_task_runner.py:77} INFO - Job 48: Subtask determine_integrity
[2021-10-03 06:35:53,154] {standard_task_runner.py:52} INFO - Started process 836 to run task
[2021-10-03 06:35:53,984] {logging_mixin.py:109} INFO - Running <TaskInstance: dag1.determine_integrity 2021-10-01T00:19:00+00:00 [running]> on host 405455ff482b
[2021-10-03 06:35:55,499] {taskinstance.py:1254} INFO - Exporting the following env vars:
AIRFLOW_CTX_DAG_EMAIL=mrk.jse@gmail.com
AIRFLOW_CTX_DAG_OWNER=***
AIRFLOW_CTX_DAG_ID=dag1
AIRFLOW_CTX_TASK_ID=determine_integrity
AIRFLOW_CTX_EXECUTION_DATE=2021-10-01T00:19:00+00:00
AIRFLOW_CTX_DAG_RUN_ID=scheduled__2021-10-01T00:19:00+00:00
[2021-10-03 06:35:55,668] {logging_mixin.py:109} INFO - Partition size: 10
[2021-10-03 06:35:55,688] {python.py:151} INFO - Done. Returned value was: <Task(PythonOperator): partition_transaction_files>
[2021-10-03 06:35:55,816] {skipmixin.py:124} INFO - Following branch <Task(PythonOperator): partition_transaction_files>
[2021-10-03 06:35:55,888] {taskinstance.py:1463} ERROR - Task failed with exception
Traceback (most recent call last):
  File "/home/airflow/.local/lib/python3.6/site-packages/airflow/models/taskinstance.py", line 1165, in _run_raw_task
    self._prepare_and_execute_task_with_callbacks(context, task)
  File "/home/airflow/.local/lib/python3.6/site-packages/airflow/models/taskinstance.py", line 1283, in _prepare_and_execute_task_with_callbacks
    result = self._execute_task(context, task_copy)
  File "/home/airflow/.local/lib/python3.6/site-packages/airflow/models/taskinstance.py", line 1313, in _execute_task
    result = task_copy.execute(context=context)
  File "/home/airflow/.local/lib/python3.6/site-packages/airflow/operators/python.py", line 180, in execute
    self.skip_all_except(context['ti'], branch)
  File "/home/airflow/.local/lib/python3.6/site-packages/airflow/models/skipmixin.py", line 128, in skip_all_except
    branch_task_ids = set(branch_task_ids)
TypeError: 'PythonOperator' object is not iterable
[2021-10-03 06:35:56,049] {taskinstance.py:1513} INFO - Marking task as FAILED. dag_id=dag1, task_id=determine_integrity, execution_date=20211001T001900, start_date=20211003T063552, end_date=20211003T063556
[2021-10-03 06:35:57,589] {logging_mixin.py:109} WARNING - /home/***/.local/lib/python3.6/site-packages/***/utils/email.py:102 PendingDeprecationWarning: Fetching SMTP credentials from configuration variables will be deprecated in a future release. Please set credentials using a connection instead.
[2021-10-03 06:35:57,645] {configuration.py:365} WARNING - section/key [smtp/smtp_user] not found in config
[2021-10-03 06:35:57,658] {email.py:208} INFO - Email alerting: attempt 1
[2021-10-03 06:35:58,735] {configuration.py:365} WARNING - section/key [smtp/smtp_user] not found in config
[2021-10-03 06:35:58,754] {email.py:208} INFO - Email alerting: attempt 1
[2021-10-03 06:35:58,767] {taskinstance.py:1519} ERROR - Failed to send email to: ['mrk.jse@gmail.com']
Traceback (most recent call last):
  File "/home/airflow/.local/lib/python3.6/site-packages/airflow/models/taskinstance.py", line 1165, in _run_raw_task
    self._prepare_and_execute_task_with_callbacks(context, task)
  File "/home/airflow/.local/lib/python3.6/site-packages/airflow/models/taskinstance.py", line 1283, in _prepare_and_execute_task_with_callbacks
    result = self._execute_task(context, task_copy)
  File "/home/airflow/.local/lib/python3.6/site-packages/airflow/models/taskinstance.py", line 1313, in _execute_task
    result = task_copy.execute(context=context)
  File "/home/airflow/.local/lib/python3.6/site-packages/airflow/operators/python.py", line 180, in execute
    self.skip_all_except(context['ti'], branch)
  File "/home/airflow/.local/lib/python3.6/site-packages/airflow/models/skipmixin.py", line 128, in skip_all_except
    branch_task_ids = set(branch_task_ids)
TypeError: 'PythonOperator' object is not iterable

During handling of the above exception, another exception occurred:

Traceback (most recent call last):
  File "/home/airflow/.local/lib/python3.6/site-packages/airflow/models/taskinstance.py", line 1858, in email_alert
    send_email(self.task.email, subject, html_content)
  File "/home/airflow/.local/lib/python3.6/site-packages/airflow/utils/email.py", line 66, in send_email
    **kwargs,
  File "/home/airflow/.local/lib/python3.6/site-packages/airflow/utils/email.py", line 102, in send_email_smtp
    send_mime_email(e_from=smtp_mail_from, e_to=recipients, mime_msg=msg, conn_id=conn_id, dryrun=dryrun)
  File "/home/airflow/.local/lib/python3.6/site-packages/airflow/utils/email.py", line 210, in send_mime_email
    conn = _get_smtp_connection(smtp_host, smtp_port, smtp_timeout, smtp_ssl)
  File "/home/airflow/.local/lib/python3.6/site-packages/airflow/utils/email.py", line 244, in _get_smtp_connection
    else smtplib.SMTP(host=host, port=port, timeout=timeout)
  File "/usr/local/lib/python3.6/smtplib.py", line 251, in __init__
    (code, msg) = self.connect(host, port)
  File "/usr/local/lib/python3.6/smtplib.py", line 336, in connect
    self.sock = self._get_socket(host, port, self.timeout)
  File "/usr/local/lib/python3.6/smtplib.py", line 307, in _get_socket
    self.source_address)
  File "/usr/local/lib/python3.6/socket.py", line 724, in create_connection
    raise err
  File "/usr/local/lib/python3.6/socket.py", line 713, in create_connection
    sock.connect(sa)
OSError: [Errno 99] Cannot assign requested address

During handling of the above exception, another exception occurred:

Traceback (most recent call last):
  File "/home/airflow/.local/lib/python3.6/site-packages/airflow/models/taskinstance.py", line 1517, in handle_failure
    self.email_alert(error)
  File "/home/airflow/.local/lib/python3.6/site-packages/airflow/models/taskinstance.py", line 1860, in email_alert
    send_email(self.task.email, subject, html_content_err)
  File "/home/airflow/.local/lib/python3.6/site-packages/airflow/utils/email.py", line 66, in send_email
    **kwargs,
  File "/home/airflow/.local/lib/python3.6/site-packages/airflow/utils/email.py", line 102, in send_email_smtp
    send_mime_email(e_from=smtp_mail_from, e_to=recipients, mime_msg=msg, conn_id=conn_id, dryrun=dryrun)
  File "/home/airflow/.local/lib/python3.6/site-packages/airflow/utils/email.py", line 210, in send_mime_email
    conn = _get_smtp_connection(smtp_host, smtp_port, smtp_timeout, smtp_ssl)
  File "/home/airflow/.local/lib/python3.6/site-packages/airflow/utils/email.py", line 244, in _get_smtp_connection
    else smtplib.SMTP(host=host, port=port, timeout=timeout)
  File "/usr/local/lib/python3.6/smtplib.py", line 251, in __init__
    (code, msg) = self.connect(host, port)
  File "/usr/local/lib/python3.6/smtplib.py", line 336, in connect
    self.sock = self._get_socket(host, port, self.timeout)
  File "/usr/local/lib/python3.6/smtplib.py", line 307, in _get_socket
    self.source_address)
  File "/usr/local/lib/python3.6/socket.py", line 724, in create_connection
    raise err
  File "/usr/local/lib/python3.6/socket.py", line 713, in create_connection
    sock.connect(sa)
OSError: [Errno 99] Cannot assign requested address
[2021-10-03 06:35:59,293] {local_task_job.py:209} WARNING - State of this instance has been externally set to failed. Terminating instance.
[2021-10-03 06:35:59,646] {process_utils.py:100} INFO - Sending Signals.SIGTERM to GPID 836
[2021-10-03 06:36:00,556] {process_utils.py:66} INFO - Process psutil.Process(pid=836, status='terminated', exitcode=1, started='06:35:52') (836) terminated with exit code 1
