[2021-10-03 06:59:34,001] {taskinstance.py:903} INFO - Dependencies all met for <TaskInstance: dag2.determine_hdfs_partitions 2021-10-03T06:59:30.580887+00:00 [queued]>
[2021-10-03 06:59:34,021] {taskinstance.py:903} INFO - Dependencies all met for <TaskInstance: dag2.determine_hdfs_partitions 2021-10-03T06:59:30.580887+00:00 [queued]>
[2021-10-03 06:59:34,022] {taskinstance.py:1095} INFO - 
--------------------------------------------------------------------------------
[2021-10-03 06:59:34,023] {taskinstance.py:1096} INFO - Starting attempt 1 of 1
[2021-10-03 06:59:34,024] {taskinstance.py:1097} INFO - 
--------------------------------------------------------------------------------
[2021-10-03 06:59:34,047] {taskinstance.py:1115} INFO - Executing <Task(BranchPythonOperator): determine_hdfs_partitions> on 2021-10-03T06:59:30.580887+00:00
[2021-10-03 06:59:34,064] {standard_task_runner.py:52} INFO - Started process 2093 to run task
[2021-10-03 06:59:34,074] {standard_task_runner.py:76} INFO - Running: ['***', 'tasks', 'run', 'dag2', 'determine_hdfs_partitions', '2021-10-03T06:59:30.580887+00:00', '--job-id', '72', '--pool', 'default_pool', '--raw', '--subdir', 'DAGS_FOLDER/historical_restate.py', '--cfg-path', '/tmp/tmp4fv3otah', '--error-file', '/tmp/tmpi2v3dtzw']
[2021-10-03 06:59:34,078] {standard_task_runner.py:77} INFO - Job 72: Subtask determine_hdfs_partitions
[2021-10-03 06:59:34,175] {logging_mixin.py:109} INFO - Running <TaskInstance: dag2.determine_hdfs_partitions 2021-10-03T06:59:30.580887+00:00 [running]> on host 405455ff482b
[2021-10-03 06:59:34,248] {taskinstance.py:1254} INFO - Exporting the following env vars:
AIRFLOW_CTX_DAG_EMAIL=mrk.jse@gmail.com
AIRFLOW_CTX_DAG_OWNER=***
AIRFLOW_CTX_DAG_ID=dag2
AIRFLOW_CTX_TASK_ID=determine_hdfs_partitions
AIRFLOW_CTX_EXECUTION_DATE=2021-10-03T06:59:30.580887+00:00
AIRFLOW_CTX_DAG_RUN_ID=manual__2021-10-03T06:59:30.580887+00:00
[2021-10-03 06:59:34,266] {logging_mixin.py:109} INFO - Partition size: 31
[2021-10-03 06:59:34,267] {python.py:151} INFO - Done. Returned value was: partition_transaction_files
[2021-10-03 06:59:34,268] {skipmixin.py:124} INFO - Following branch partition_transaction_files
[2021-10-03 06:59:34,297] {taskinstance.py:1463} ERROR - Task failed with exception
Traceback (most recent call last):
  File "/home/airflow/.local/lib/python3.6/site-packages/airflow/models/taskinstance.py", line 1165, in _run_raw_task
    self._prepare_and_execute_task_with_callbacks(context, task)
  File "/home/airflow/.local/lib/python3.6/site-packages/airflow/models/taskinstance.py", line 1283, in _prepare_and_execute_task_with_callbacks
    result = self._execute_task(context, task_copy)
  File "/home/airflow/.local/lib/python3.6/site-packages/airflow/models/taskinstance.py", line 1313, in _execute_task
    result = task_copy.execute(context=context)
  File "/home/airflow/.local/lib/python3.6/site-packages/airflow/operators/python.py", line 180, in execute
    self.skip_all_except(context['ti'], branch)
  File "/home/airflow/.local/lib/python3.6/site-packages/airflow/models/skipmixin.py", line 150, in skip_all_except
    branch_task_ids.update(dag.get_task(branch_task_id).get_flat_relative_ids(upstream=False))
  File "/home/airflow/.local/lib/python3.6/site-packages/airflow/models/dag.py", line 1547, in get_task
    raise TaskNotFound(f"Task {task_id} not found")
airflow.exceptions.TaskNotFound: Task partition_transaction_files not found
[2021-10-03 06:59:34,303] {taskinstance.py:1513} INFO - Marking task as FAILED. dag_id=dag2, task_id=determine_hdfs_partitions, execution_date=20211003T065930, start_date=20211003T065934, end_date=20211003T065934
[2021-10-03 06:59:34,347] {logging_mixin.py:109} WARNING - /home/***/.local/lib/python3.6/site-packages/***/utils/email.py:102 PendingDeprecationWarning: Fetching SMTP credentials from configuration variables will be deprecated in a future release. Please set credentials using a connection instead.
[2021-10-03 06:59:34,349] {configuration.py:365} WARNING - section/key [smtp/smtp_user] not found in config
[2021-10-03 06:59:34,350] {email.py:208} INFO - Email alerting: attempt 1
[2021-10-03 06:59:34,368] {configuration.py:365} WARNING - section/key [smtp/smtp_user] not found in config
[2021-10-03 06:59:34,370] {email.py:208} INFO - Email alerting: attempt 1
[2021-10-03 06:59:34,371] {taskinstance.py:1519} ERROR - Failed to send email to: ['mrk.jse@gmail.com']
Traceback (most recent call last):
  File "/home/airflow/.local/lib/python3.6/site-packages/airflow/models/taskinstance.py", line 1165, in _run_raw_task
    self._prepare_and_execute_task_with_callbacks(context, task)
  File "/home/airflow/.local/lib/python3.6/site-packages/airflow/models/taskinstance.py", line 1283, in _prepare_and_execute_task_with_callbacks
    result = self._execute_task(context, task_copy)
  File "/home/airflow/.local/lib/python3.6/site-packages/airflow/models/taskinstance.py", line 1313, in _execute_task
    result = task_copy.execute(context=context)
  File "/home/airflow/.local/lib/python3.6/site-packages/airflow/operators/python.py", line 180, in execute
    self.skip_all_except(context['ti'], branch)
  File "/home/airflow/.local/lib/python3.6/site-packages/airflow/models/skipmixin.py", line 150, in skip_all_except
    branch_task_ids.update(dag.get_task(branch_task_id).get_flat_relative_ids(upstream=False))
  File "/home/airflow/.local/lib/python3.6/site-packages/airflow/models/dag.py", line 1547, in get_task
    raise TaskNotFound(f"Task {task_id} not found")
airflow.exceptions.TaskNotFound: Task partition_transaction_files not found

During handling of the above exception, another exception occurred:

Traceback (most recent call last):
  File "/home/airflow/.local/lib/python3.6/site-packages/airflow/models/taskinstance.py", line 1858, in email_alert
    send_email(self.task.email, subject, html_content)
  File "/home/airflow/.local/lib/python3.6/site-packages/airflow/utils/email.py", line 66, in send_email
    **kwargs,
  File "/home/airflow/.local/lib/python3.6/site-packages/airflow/utils/email.py", line 102, in send_email_smtp
    send_mime_email(e_from=smtp_mail_from, e_to=recipients, mime_msg=msg, conn_id=conn_id, dryrun=dryrun)
  File "/home/airflow/.local/lib/python3.6/site-packages/airflow/utils/email.py", line 210, in send_mime_email
    conn = _get_smtp_connection(smtp_host, smtp_port, smtp_timeout, smtp_ssl)
  File "/home/airflow/.local/lib/python3.6/site-packages/airflow/utils/email.py", line 244, in _get_smtp_connection
    else smtplib.SMTP(host=host, port=port, timeout=timeout)
  File "/usr/local/lib/python3.6/smtplib.py", line 251, in __init__
    (code, msg) = self.connect(host, port)
  File "/usr/local/lib/python3.6/smtplib.py", line 336, in connect
    self.sock = self._get_socket(host, port, self.timeout)
  File "/usr/local/lib/python3.6/smtplib.py", line 307, in _get_socket
    self.source_address)
  File "/usr/local/lib/python3.6/socket.py", line 724, in create_connection
    raise err
  File "/usr/local/lib/python3.6/socket.py", line 713, in create_connection
    sock.connect(sa)
OSError: [Errno 99] Cannot assign requested address

During handling of the above exception, another exception occurred:

Traceback (most recent call last):
  File "/home/airflow/.local/lib/python3.6/site-packages/airflow/models/taskinstance.py", line 1517, in handle_failure
    self.email_alert(error)
  File "/home/airflow/.local/lib/python3.6/site-packages/airflow/models/taskinstance.py", line 1860, in email_alert
    send_email(self.task.email, subject, html_content_err)
  File "/home/airflow/.local/lib/python3.6/site-packages/airflow/utils/email.py", line 66, in send_email
    **kwargs,
  File "/home/airflow/.local/lib/python3.6/site-packages/airflow/utils/email.py", line 102, in send_email_smtp
    send_mime_email(e_from=smtp_mail_from, e_to=recipients, mime_msg=msg, conn_id=conn_id, dryrun=dryrun)
  File "/home/airflow/.local/lib/python3.6/site-packages/airflow/utils/email.py", line 210, in send_mime_email
    conn = _get_smtp_connection(smtp_host, smtp_port, smtp_timeout, smtp_ssl)
  File "/home/airflow/.local/lib/python3.6/site-packages/airflow/utils/email.py", line 244, in _get_smtp_connection
    else smtplib.SMTP(host=host, port=port, timeout=timeout)
  File "/usr/local/lib/python3.6/smtplib.py", line 251, in __init__
    (code, msg) = self.connect(host, port)
  File "/usr/local/lib/python3.6/smtplib.py", line 336, in connect
    self.sock = self._get_socket(host, port, self.timeout)
  File "/usr/local/lib/python3.6/smtplib.py", line 307, in _get_socket
    self.source_address)
  File "/usr/local/lib/python3.6/socket.py", line 724, in create_connection
    raise err
  File "/usr/local/lib/python3.6/socket.py", line 713, in create_connection
    sock.connect(sa)
OSError: [Errno 99] Cannot assign requested address
[2021-10-03 06:59:34,432] {local_task_job.py:151} INFO - Task exited with return code 1
[2021-10-03 06:59:34,611] {local_task_job.py:261} INFO - 0 downstream tasks scheduled from follow-on schedule check
